Workbook

Sheet 1-7-26
A1: DIGITAL TITANS
A4: VISITORS
A6: Sr. No. | B6: Date | C6: Member Who Invited Visitors (Name) | D6: Visitor Name | E6: Hot Category (Count) | F6: Open Cateory (Count) | G6: Closed Category (Count) | H6: Repeat Visitor (Count) | I6: POINTS | J6: TOTAL POINTS
A8: 1 | B8: 46029 | C8: Meghna Shah | D8: Mamta Tejwani | F8: 1 | I8: =SUM((E8*300)+(F8*200)+(G8*50)+(H8*0)) -> 200 | J8: =SUM(I8:I15) -> 600
D9: Saloni | F9: 1 | I9: =SUM((E9*300)+(F9*200)+(G9*50)+(H9*0)) -> 200
I10: =SUM((E10*300)+(F10*200)+(G10*50)+(H10*0)) -> 0
B11: 46029 | C11: Harun Kazi | D11: Himanshu Trivedi | F11: 1 | I11: =SUM((E11*300)+(F11*200)+(G11*50)+(H11*0)) -> 200
I12: =SUM((E12*300)+(F12*200)+(G12*50)+(H12*0)) -> 0
I13: =SUM((E13*300)+(F13*200)+(G13*50)+(H13*0)) -> 0
I14: =SUM((E14*300)+(F14*200)+(G14*50)+(H14*0)) -> 0
I15: =SUM((E15*300)+(F15*200)+(G15*50)+(H15*0)) -> 0
A18: INDUCTIONS
A20: Sr. No. | B20: Date | C20: Sponsor Member (Name) | D20: Member Inducted (Count) | E20: POINTS | F20: TOTAL POINTS
B22: 46029 | C22: Meghna Shah | D22: 1 | E22: =(D22*500) -> 500 | F22: =SUM(E22:E29) -> 500
E23: =(D23*500) -> 0
E24: =(D24*500) -> 0
E25: =(D25*500) -> 0
E26: =(D26*500) -> 0
E27: =(D27*500) -> 0
E28: =(D28*500) -> 0
E29: =(D29*500) -> 0
A32: ATTENDANCE
A34: Sr. No. | B34: Date | C34: List Team Members Present (Name) | D34: Number of Absent Team Members | E34: TOTAL POINTS
A36: 1 | B36: 46029 | C36: Kamlesh | E36: =IF(D36=0,300,D36*-200) -> 300
A37: 2 | B37: 46029 | C37: Harun
A38: 3 | B38: 46029 | C38: Suhani
A39: 4 | B39: 46029 | C39: Meghna
A40: 5 | B40: 46029 | C40: Bhavik
A45: PUCTUALITY
A47: Sr. No. | B47: Date | C47: List Team Members Present on Time (Name) | D47: Number of Team Members Coming Late | E47: POINTS
A49: 1 | B49: 46029 | C49: Kamlesh | E49: =IF(D49=0,100,D49*-20) -> 100
A50: 2 | B50: 46029 | C50: Harun
A51: 3 | B51: 46029 | C51: Suhani
A52: 4 | B52: 46029 | C52: Meghna
A53: 5 | B53: 46029 | C53: EKta
A54: 6 | B54: 46029 | C54: Bhavik
A59: WEARING BADGE/ACHIEVER'S PINS
A61: Sr. No. | B61: Date | C61: Team Members (Name) | D61: Did this Team Member wear Badge (If yes write 1, if no write 0) | E61: POINTS | F61: TOTAL POINTS
A63: 1 | B63: 46029 | C63: Kamlesh | D63: 1 | E63: =(D63*100) -> 100 | F63: =SUM(E63:E69) -> 500
A64: 2 | B64: 46029 | C64: Harun | D64: 1 | E64: =(D64*100) -> 100
...

Sheet 15-7-26
A1: DIGITAL TITANS
A4: VISITORS
A6: Sr. No. | B6: Date | C6: Member Who Invited Visitors (Name) | D6: Visitor Name | E6: Hot Category (Count) | F6: Open Cateory (Count) | G6: Closed Category (Count) | H6: Repeat Visitor(Count) | I6: POINTS | J6: TOTAL POINTS
A8: 1 | I8: =SUM((E8*300)+(F8*200)+(G8*50)+(H8*0)) -> 0 | J8: =SUM(I8:I15) -> 0
I9: =SUM((E9*300)+(F9*200)+(G9*50)+(H9*0)) -> 0
I10: =SUM((E10*300)+(F10*200)+(G10*50)+(H10*0)) -> 0
I11: =SUM((E11*300)+(F11*200)+(G11*50)+(H11*0)) -> 0
I12: =SUM((E12*300)+(F12*200)+(G12*50)+(H12*0)) -> 0
I13: =SUM((E13*300)+(F13*200)+(G13*50)+(H13*0)) -> 0
I14: =SUM((E14*300)+(F14*200)+(G14*50)+(H14*0)) -> 0
I15: =SUM((E15*300)+(F15*200)+(G15*50)+(H15*0)) -> 0
A18: INDUCTIONS
A20: Sr. No. | B20: Date | C20: Sponsor Member (Name) | D20: Member Inducted (Count) | E20: POINTS | F20: TOTAL POINTS
E22: =(D22*500) -> 0 | F22: =SUM(E22:E29) -> 0
E23: =(D23*500) -> 0
E24: =(D24*500) -> 0
E25: =(D25*500) -> 0
E26: =(D26*500) -> 0
E27: =(D27*500) -> 0
E28: =(D28*500) -> 0
E29: =(D29*500) -> 0
A32: REFERRALS
A34: Sr. No. | B34: Date | C34: Team Members (Name) | D34: Same Team (Count) | E34: Cross Team/Chapter (Count) | F34: Cross Region/ Commissioner (Count) | G34: POINTS | H34: TOTAL POINTS
G36: =SUM((D36*50)+(E36*100)+(F36*150)) -> 0 | H36: =SUM(G36:G43) -> 0
G37: =SUM((D37*50)+(E37*100)+(F37*150)) -> 0
G38: =SUM((D38*50)+(E38*100)+(F38*150)) -> 0
G39: =SUM((D39*50)+(E39*100)+(F39*150)) -> 0
G40: =SUM((D40*50)+(E40*100)+(F40*150)) -> 0
G41: =SUM((D41*50)+(E41*100)+(F41*150)) -> 0
G42: =SUM((D42*50)+(E42*100)+(F42*150)) -> 0
G43: =SUM((D43*50)+(E43*100)+(F43*150)) -> 0
A46: V2V
A48: Sr. No. | B48: Date | C48: Team Members (Name) | D48: Same Team (Count) | E48: Cross Team/ Chapter/Commissioner (Count) | F48: Cross Region (Count) | G48: ED (Count) | H48: POINTS | I48: TOTAL POINTS
H50: =((D50*50)+(E50*150)+(F50*200)+(G50*300)) -> 0 | I50: =SUM(H50:H62) -> 0
H51: =((D51*50)+(E51*150)+(F51*200)+(G51*300)) -> 0
H52: =((D52*50)+(E52*150)+(F52*200)+(G52*300)) -> 0
H53: =((D53*50)+(E53*150)+(F53*200)+(G53*300)) -> 0
H54: =((D54*50)+(E54*150)+(F54*200)+(G54*300)) -> 0
H55: =((D55*50)+(E55*150)+(F55*200)+(G55*300)) -> 0
H56: =((D56*50)+(E56*150)+(F56*200)+(G56*300)) -> 0
...

Sheet 29-7-26
A1: DIGITAL TITANS
A4: VISITORS
A6: Sr. No. | B6: Date | C6: Member Who Invited Visitors (Name) | D6: Visitor Name | E6: Hot Category (Count) | F6: Open Cateory (Count) | G6: Closed Category (Count) | H6: Repeat Visitor(Count) | I6: POINTS | J6: TOTAL POINTS
A8: 1 | I8: =SUM((E8*300)+(F8*200)+(G8*50)+(H8*0)) -> 0 | J8: =SUM(I8:I15) -> 0
I9: =SUM((E9*300)+(F9*200)+(G9*50)+(H9*0)) -> 0
I10: =SUM((E10*300)+(F10*200)+(G10*50)+(H10*0)) -> 0
I11: =SUM((E11*300)+(F11*200)+(G11*50)+(H11*0)) -> 0
I12: =SUM((E12*300)+(F12*200)+(G12*50)+(H12*0)) -> 0
I13: =SUM((E13*300)+(F13*200)+(G13*50)+(H13*0)) -> 0
I14: =SUM((E14*300)+(F14*200)+(G14*50)+(H14*0)) -> 0
I15: =SUM((E15*300)+(F15*200)+(G15*50)+(H15*0)) -> 0
A18: INDUCTIONS
A20: Sr. No. | B20: Date | C20: Sponsor Member (Name) | D20: Member Inducted (Count) | E20: POINTS | F20: TOTAL POINTS
E22: =(D22*500) -> 0 | F22: =SUM(E22:E29) -> 0
E23: =(D23*500) -> 0
E24: =(D24*500) -> 0
E25: =(D25*500) -> 0
E26: =(D26*500) -> 0
E27: =(D27*500) -> 0
E28: =(D28*500) -> 0
E29: =(D29*500) -> 0
A32: REFERRALS
A34: Sr. No. | B34: Date | C34: Team Members (Name) | D34: Same Team (Count) | E34: Cross Team/Chapter (Count) | F34: Cross Region/ Commissioner (Count) | G34: POINTS | H34: TOTAL POINTS
G36: =SUM((D36*50)+(E36*100)+(F36*150)) -> 0 | H36: =SUM(G36:G43) -> 0
G37: =SUM((D37*50)+(E37*100)+(F37*150)) -> 0
G38: =SUM((D38*50)+(E38*100)+(F38*150)) -> 0
G39: =SUM((D39*50)+(E39*100)+(F39*150)) -> 0
G40: =SUM((D40*50)+(E40*100)+(F40*150)) -> 0
G41: =SUM((D41*50)+(E41*100)+(F41*150)) -> 0
G42: =SUM((D42*50)+(E42*100)+(F42*150)) -> 0
G43: =SUM((D43*50)+(E43*100)+(F43*150)) -> 0
A46: V2V
A48: Sr. No. | B48: Date | C48: Team Members (Name) | D48: Same Team (Count) | E48: Cross Team/ Chapter/Commissioner (Count) | F48: Cross Region (Count) | G48: ED (Count) | H48: POINTS | I48: TOTAL POINTS
H50: =((D50*50)+(E50*150)+(F50*200)+(G50*300)) -> 0 | I50: =SUM(H50:H62) -> 0
H51: =((D51*50)+(E51*150)+(F51*200)+(G51*300)) -> 0
H52: =((D52*50)+(E52*150)+(F52*200)+(G52*300)) -> 0
H53: =((D53*50)+(E53*150)+(F53*200)+(G53*300)) -> 0
H54: =((D54*50)+(E54*150)+(F54*200)+(G54*300)) -> 0
H55: =((D55*50)+(E55*150)+(F55*200)+(G55*300)) -> 0
H56: =((D56*50)+(E56*150)+(F56*200)+(G56*300)) -> 0
...

Sheet 12-8-26
A1: DIGITAL TITANS
A4: VISITORS
A6: Sr. No. | B6: Date | C6: Member Who Invited Visitors (Name) | D6: Visitor Name | E6: Hot Category (Count) | F6: Open Cateory (Count) | G6: Closed Category (Count) | H6: Repeat Visitor (Count) | I6: POINTS | J6: TOTAL POINTS
I8: =SUM((E8*300)+F8*200)+(G8*50)+(H8*0) -> 0 | J8: =SUM(I7:I15) -> 0
I9: =SUM((E9*300)+F9*200)+(G9*50)+(H9*0) -> 0
I10: =SUM((E10*300)+F10*200)+(G10*50)+(H10*0) -> 0
I11: =SUM((E11*300)+F11*200)+(G11*50)+(H11*0) -> 0
I12: =SUM((E12*300)+F12*200)+(G12*50)+(H12*0) -> 0
I13: =SUM((E13*300)+F13*200)+(G13*50)+(H13*0) -> 0
I14: =SUM((E14*300)+F14*200)+(G14*50)+(H14*0) -> 0
I15: =SUM((E15*300)+F15*200)+(G15*50)+(H15*0) -> 0
A18: INDUCTIONS
A20: Sr. No. | B20: Date | C20: Sponsor Member (Name) | D20: Member Inducted (Count) | E20: POINTS | F20: TOTAL POINTS
E22: =(D22*500) -> 0 | F22: =SUM(E22:E29) -> 0
E23: =(D23*500) -> 0
E24: =(D24*500) -> 0
E25: =(D25*500) -> 0
E26: =(D26*500) -> 0
E27: =(D27*500) -> 0
E28: =(D28*500) -> 0
E29: =(D29*500) -> 0
A32: REFERRALS
A34: Sr. No. | B34: Date | C34: Team Members (Name) | D34: Same Team (Count) | E34: Cross Team/Chapter (Count) | F34: Cross Region/Commissioner (Count) | G34: POINTS | H34: TOTAL POINTS
G36: =SUM((D36*50)+(E36*100)+(F36*150)) -> 0 | H36: =SUM(G36:G43) -> 0
G37: =SUM((D37*50)+(E37*100)+(F37*150)) -> 0
G38: =SUM((D38*50)+(E38*100)+(F38*150)) -> 0
G39: =SUM((D39*50)+(E39*100)+(F39*150)) -> 0
G40: =SUM((D40*50)+(E40*100)+(F40*150)) -> 0
G41: =SUM((D41*50)+(E41*100)+(F41*150)) -> 0
G42: =SUM((D42*50)+(E42*100)+(F42*150)) -> 0
G43: =SUM((D43*50)+(E43*100)+(F43*150)) -> 0
A46: V2V
A48: Sr. No. | B48: Date | C48: Team Members (Name) | D48: Same Team (Count) | E48: Cross Team/ Chapter/Commissioner (Count) | F48: Cross Region (Count) | G48: ED (Count) | H48: POINTS | I48: TOTAL POINTS
H50: =((D50*50)+(E50*150)+(F50*200)+(G50*300)) -> 0 | I50: =SUM(H50:H62) -> 0
H51: =((D51*50)+(E51*150)+(F51*200)+(G51*300)) -> 0
H52: =((D52*50)+(E52*150)+(F52*200)+(G52*300)) -> 0
H53: =((D53*50)+(E53*150)+(F53*200)+(G53*300)) -> 0
H54: =((D54*50)+(E54*150)+(F54*200)+(G54*300)) -> 0
H55: =((D55*50)+(E55*150)+(F55*200)+(G55*300)) -> 0
H56: =((D56*50)+(E56*150)+(F56*200)+(G56*300)) -> 0
...

Sheet 26-8-26
A1: DIGITAL TITANS
A4: VISITORS
A6: Sr. No. | B6: Date | C6: Member Who Invited Visitors (Name) | D6: Visitor Name | E6: Hot Category (Count) | F6: Open Cateory (Count) | G6: Closed Category (Count) | H6: Repeat Visitor (Count) | I6: POINTS | J6: TOTAL POINTS
I8: =SUM((E8*300)+F8*200)+(G8*50)+(H8*0) -> 0 | J8: =SUM(I7:I15) -> 0
I9: =SUM((E9*300)+F9*200)+(G9*50)+(H9*0) -> 0
I10: =SUM((E10*300)+F10*200)+(G10*50)+(H10*0) -> 0
I11: =SUM((E11*300)+F11*200)+(G11*50)+(H11*0) -> 0
I12: =SUM((E12*300)+F12*200)+(G12*50)+(H12*0) -> 0
I13: =SUM((E13*300)+F13*200)+(G13*50)+(H13*0) -> 0
I14: =SUM((E14*300)+F14*200)+(G14*50)+(H14*0) -> 0
I15: =SUM((E15*300)+F15*200)+(G15*50)+(H15*0) -> 0
A18: INDUCTIONS
A20: Sr. No. | B20: Date | C20: Sponsor Member (Name) | D20: Member Inducted (Count) | E20: POINTS | F20: TOTAL POINTS
E22: =(D22*500) -> 0 | F22: =SUM(E22:E29) -> 0
E23: =(D23*500) -> 0
E24: =(D24*500) -> 0
E25: =(D25*500) -> 0
E26: =(D26*500) -> 0
E27: =(D27*500) -> 0
E28: =(D28*500) -> 0
E29: =(D29*500) -> 0
A32: REFERRALS
A34: Sr. No. | B34: Date | C34: Team Members (Name) | D34: Same Team (Count) | E34: Cross Team/Chapter (Count) | F34: Cross Region/Commissioner (Count) | G34: POINTS | H34: TOTAL POINTS
G36: =SUM((D36*50)+(E36*100)+(F36*150)) -> 0 | H36: =SUM(G36:G43) -> 0
G37: =SUM((D37*50)+(E37*100)+(F37*150)) -> 0
G38: =SUM((D38*50)+(E38*100)+(F38*150)) -> 0
G39: =SUM((D39*50)+(E39*100)+(F39*150)) -> 0
G40: =SUM((D40*50)+(E40*100)+(F40*150)) -> 0
G41: =SUM((D41*50)+(E41*100)+(F41*150)) -> 0
G42: =SUM((D42*50)+(E42*100)+(F42*150)) -> 0
G43: =SUM((D43*50)+(E43*100)+(F43*150)) -> 0
A46: V2V
A48: Sr. No. | B48: Date | C48: Team Members (Name) | D48: Same Team (Count) | E48: Cross Team/ Chapter/Commissioner (Count) | F48: Cross Region (Count) | G48: ED (Count) | H48: POINTS | I48: TOTAL POINTS
H50: =((D50*50)+(E50*150)+(F50*200)+(G50*300)) -> 0 | I50: =SUM(H50:H62) -> 0
H51: =((D51*50)+(E51*150)+(F51*200)+(G51*300)) -> 0
H52: =((D52*50)+(E52*150)+(F52*200)+(G52*300)) -> 0
H53: =((D53*50)+(E53*150)+(F53*200)+(G53*300)) -> 0
H54: =((D54*50)+(E54*150)+(F54*200)+(G54*300)) -> 0
H55: =((D55*50)+(E55*150)+(F55*200)+(G55*300)) -> 0
H56: =((D56*50)+(E56*150)+(F56*200)+(G56*300)) -> 0
...

Sheet Summery
B3: Pluto Premier League - Team Name Score Summary
E6: Timeline | F6: Score | G6: Total
E8: Meeting 1 | F8: ='1-7-26'!C132 -> 1900 | G8: =SUM(F8,F9,F10,F11,F12) -> 3500
E9: Meeting 2 | F9: ='15-7-26'!C269 -> 400
E10: Meeting 3 | F10: ='29-7-26'!C269 -> 400
E11: Meeting 4 | F11: ='12-8-26'!C269 -> 400
E12: Meeting 5 | F12: ='26-8-26'!C269 -> 400
